<mujoco model="go2_description">
  <compiler angle="radian"/>
  <worldbody>
    <body name="base">
      <inertial pos="0.021112 0 -0.005366" quat="-0.000543471 0.713435 -0.00173769 0.700719" mass="6.921" diaginertia="0.107027 0.0980771 0.0244531"/>
      <joint name="floating_base_joint" type="free" limited="false" actuatorfrclimited="false"/>
      <geom size="0.1881 0.04675 0.057" type="box" rgba="1 1 1 1"/>
      <body name="Head_upper" pos="0.285 0 0.01">
        <inertial pos="0 0 0" mass="0.001" diaginertia="9.6e-06 9.6e-06 9.6e-06"/>
        <geom size="0.05 0.045" type="cylinder"/>
        <body name="Head_lower" pos="0.008 0 -0.07">
          <inertial pos="0 0 0" mass="0.001" diaginertia="9.6e-06 9.6e-06 9.6e-06"/>
          <geom size="0.047"/>
        </body>
      </body>
      <body name="FL_hip" pos="0.1934 0.0465 0">
        <inertial pos="-0.0054 0.00194 -0.000105" quat="0.497014 0.499245 0.505462 0.498237" mass="0.678" diaginertia="0.00088403 0.000596003 0.000479967"/>
        <joint name="FL_hip_joint" pos="0 0 0" axis="1 0 0" limited="true" range="-1.0472 1.0472"/>
        <geom size="0.046 0.02" pos="0 0.08 0" quat="0.707107 0.707107 0 0" type="cylinder" rgba="1 1 1 1"/>
        <body name="FL_thigh" pos="0 0.0955 0">
          <inertial pos="-0.00374 -0.0223 -0.0327" quat="0.829533 0.0847635 -0.0200632 0.551623" mass="1.152" diaginertia="0.00594973 0.00584149 0.000878787"/>
          <joint name="FL_thigh_joint" pos="0 0 0" axis="0 1 0" limited="true" range="-1.5708 3.4907"/>
          <geom size="0.1065 0.01225 0.017" pos="0 0 -0.1065" quat="0.707107 0 0.707107 0" type="box" rgba="1 1 1 1"/>
          <body name="FL_calf" pos="0 0 -0.213">
            <inertial pos="0.00548 -0.000975 -0.115" quat="0.715503 -0.00296111 -0.00858046 0.698551" mass="0.154" diaginertia="0.00110008 0.00108027 3.25534e-05"/>
            <joint name="FL_calf_joint" pos="0 0 0" axis="0 1 0" limited="true" range="-2.7227 -0.83776"/>
            <geom size="0.012 0.06" pos="0.008 0 -0.06" quat="0.994493 0 -0.104807 0" type="cylinder" rgba="1 1 1 1"/>
            <body name="FL_calflower" pos="0.02 0 -0.148" quat="0.999688 0 0.0249974 0">
              <geom size="0.011 0.0325" type="cylinder"/>
              <body name="FL_calflower1" pos="-0.01 0 -0.04" quat="0.971338 0 0.237703 0">
                <geom size="0.0155 0.015" type="cylinder"/>
              </body>
            </body>
            <body name="FL_foot" pos="0 0 -0.213">
              <inertial pos="0 0 0" mass="0.04" diaginertia="9.6e-06 9.6e-06 9.6e-06"/>
              <geom size="0.022" pos="-0.002 0 0" rgba="1 1 1 1"/>
            </body>
          </body>
        </body>
      </body>
      <body name="FR_hip" pos="0.1934 -0.0465 0">
        <inertial pos="-0.0054 -0.00194 -0.000105" quat="0.498237 0.505462 0.499245 0.497014" mass="0.678" diaginertia="0.00088403 0.000596003 0.000479967"/>
        <joint name="FR_hip_joint" pos="0 0 0" axis="1 0 0" limited="true" range="-1.0472 1.0472"/>
        <geom size="0.046 0.02" pos="0 -0.08 0" quat="0.707107 0.707107 0 0" type="cylinder" rgba="1 1 1 1"/>
        <body name="FR_thigh" pos="0 -0.0955 0">
          <inertial pos="-0.00374 0.0223 -0.0327" quat="0.551623 -0.0200632 0.0847635 0.829533" mass="1.152" diaginertia="0.00594973 0.00584149 0.000878787"/>
          <joint name="FR_thigh_joint" pos="0 0 0" axis="0 1 0" limited="true" range="-1.5708 3.4907"/>
          <geom size="0.1065 0.01225 0.017" pos="0 0 -0.1065" quat="0.707107 0 0.707107 0" type="box" rgba="1 1 1 1"/>
          <body name="FR_calf" pos="0 0 -0.213">
            <inertial pos="0.00548 0.000975 -0.115" quat="0.698551 -0.00858046 -0.00296111 0.715503" mass="0.154" diaginertia="0.00110008 0.00108027 3.25534e-05"/>
            <joint name="FR_calf_joint" pos="0 0 0" axis="0 1 0" limited="true" range="-2.7227 -0.83776"/>
            <geom size="0.013 0.06" pos="0.01 0 -0.06" quat="0.995004 0 -0.0998334 0" type="cylinder" rgba="1 1 1 1"/>
            <body name="FR_calflower" pos="0.02 0 -0.148" quat="0.999688 0 0.0249974 0">
              <geom size="0.011 0.0325" type="cylinder"/>
              <body name="FR_calflower1" pos="-0.01 0 -0.04" quat="0.971338 0 0.237703 0">
                <geom size="0.0155 0.015" type="cylinder"/>
              </body>
            </body>
            <body name="FR_foot" pos="0 0 -0.213">
              <inertial pos="0 0 0" mass="0.04" diaginertia="9.6e-06 9.6e-06 9.6e-06"/>
              <geom size="0.022" pos="-0.002 0 0" rgba="1 1 1 1"/>
            </body>
          </body>
        </body>
      </body>
      <body name="RL_hip" pos="-0.1934 0.0465 0">
        <inertial pos="0.0054 0.00194 -0.000105" quat="0.505462 0.498237 0.497014 0.499245" mass="0.678" diaginertia="0.00088403 0.000596003 0.000479967"/>
        <joint name="RL_hip_joint" pos="0 0 0" axis="1 0 0" limited="true" range="-1.0472 1.0472"/>
        <geom size="0.046 0.02" pos="0 0.08 0" quat="0.707107 0.707107 0 0" type="cylinder" rgba="1 1 1 1"/>
        <body name="RL_thigh" pos="0 0.0955 0">
          <inertial pos="-0.00374 -0.0223 -0.0327" quat="0.829533 0.0847635 -0.0200632 0.551623" mass="1.152" diaginertia="0.00594973 0.00584149 0.000878787"/>
          <joint name="RL_thigh_joint" pos="0 0 0" axis="0 1 0" limited="true" range="-0.5236 4.5379"/>
          <geom size="0.1065 0.01225 0.017" pos="0 0 -0.1065" quat="0.707107 0 0.707107 0" type="box" rgba="1 1 1 1"/>
          <body name="RL_calf" pos="0 0 -0.213">
            <inertial pos="0.00548 -0.000975 -0.115" quat="0.715503 -0.00296111 -0.00858046 0.698551" mass="0.154" diaginertia="0.00110008 0.00108027 3.25534e-05"/>
            <joint name="RL_calf_joint" pos="0 0 0" axis="0 1 0" limited="true" range="-2.7227 -0.83776"/>
            <geom size="0.013 0.06" pos="0.01 0 -0.06" quat="0.995004 0 -0.0998334 0" type="cylinder" rgba="1 1 1 1"/>
            <body name="RL_calflower" pos="0.02 0 -0.148" quat="0.999688 0 0.0249974 0">
              <geom size="0.011 0.0325" type="cylinder"/>
              <body name="RL_calflower1" pos="-0.01 0 -0.04" quat="0.971338 0 0.237703 0">
                <geom size="0.0155 0.015" type="cylinder"/>
              </body>
            </body>
            <body name="RL_foot" pos="0 0 -0.213">
              <inertial pos="0 0 0" mass="0.04" diaginertia="9.6e-06 9.6e-06 9.6e-06"/>
              <geom size="0.022" pos="-0.002 0 0" rgba="1 1 1 1"/>
            </body>
          </body>
        </body>
      </body>
      <body name="RR_hip" pos="-0.1934 -0.0465 0">
        <inertial pos="0.0054 -0.00194 -0.000105" quat="0.499245 0.497014 0.498237 0.505462" mass="0.678" diaginertia="0.00088403 0.000596003 0.000479967"/>
        <joint name="RR_hip_joint" pos="0 0 0" axis="1 0 0" limited="true" range="-1.0472 1.0472"/>
        <geom size="0.046 0.02" pos="0 -0.08 0" quat="0.707107 0.707107 0 0" type="cylinder" rgba="1 1 1 1"/>
        <body name="RR_thigh" pos="0 -0.0955 0">
          <inertial pos="-0.00374 0.0223 -0.0327" quat="0.551623 -0.0200632 0.0847635 0.829533" mass="1.152" diaginertia="0.00594973 0.00584149 0.000878787"/>
          <joint name="RR_thigh_joint" pos="0 0 0" axis="0 1 0" limited="true" range="-0.5236 4.5379"/>
          <geom size="0.1065 0.01225 0.017" pos="0 0 -0.1065" quat="0.707107 0 0.707107 0" type="box" rgba="1 1 1 1"/>
          <body name="RR_calf" pos="0 0 -0.213">
            <inertial pos="0.00548 0.000975 -0.115" quat="0.698551 -0.00858046 -0.00296111 0.715503" mass="0.154" diaginertia="0.00110008 0.00108027 3.25534e-05"/>
            <joint name="RR_calf_joint" pos="0 0 0" axis="0 1 0" limited="true" range="-2.7227 -0.83776"/>
            <geom size="0.013 0.06" pos="0.01 0 -0.06" quat="0.995004 0 -0.0998334 0" type="cylinder" rgba="1 1 1 1"/>
            <body name="RR_calflower" pos="0.02 0 -0.148" quat="0.999688 0 0.0249974 0">
              <geom size="0.011 0.0325" type="cylinder"/>
              <body name="RR_calflower1" pos="-0.01 0 -0.04" quat="0.971338 0 0.237703 0">
                <geom size="0.0155 0.015" type="cylinder"/>
              </body>
            </body>
            <body name="RR_foot" pos="0 0 -0.213">
              <inertial pos="0 0 0" mass="0.04" diaginertia="9.6e-06 9.6e-06 9.6e-06"/>
              <geom size="0.022" pos="-0.002 0 0" rgba="1 1 1 1"/>
            </body>
          </body>
        </body>
      </body>
      <!-- <body name="imu" pos="-0.02557 0 0.04232">
        <inertial pos="0 0 0" mass="0" diaginertia="0 0 0"/>
      </body>
      <body name="radar" pos="0.28945 0 -0.046825" quat="0.131316 0 0.991341 0">
        <inertial pos="0 0 0" mass="0" diaginertia="0 0 0"/>
      </body> -->
    </body>
  </worldbody>
</mujoco>
